Workbook
Name PF12: '3. BASE VARIABLES'!$H$39:$H$1416
Name PF18: '3. BASE VARIABLES'!$H$1474:$H$1478
Name PF2: '3. BASE VARIABLES'!$H$1482:$H$1492
Name PF4: '3. BASE VARIABLES'!$H$1783:$H$2041
Name PF5: '3. BASE VARIABLES'!$H$2042:$H$2300
Name PF6: '3. BASE VARIABLES'!$H$2301:$H$2559
Name PF7: '3. BASE VARIABLES'!$H$2560:$H$2592
Name PFF1: '3. BASE VARIABLES'!$H$2635:$H$2642
Name PFF2: '3. BASE VARIABLES'!$H$2643:$H$2647
Name PFF3: '3. BASE VARIABLES'!$H$2648:$H$2652
Name PFF4: '3. BASE VARIABLES'!$H$2653:$H$2656
Name PFF5: '3. BASE VARIABLES'!$H$2657:$H$2660
Name PFF6: '3. BASE VARIABLES'!$H$2661:$H$2663
Name PFF7: '3. BASE VARIABLES'!$H$2664:$H$2667
Name PFF8: '3. BASE VARIABLES'!$H$2668:$H$2670
Name PFF9: '3. BASE VARIABLES'!$H$2671:$H$2673
Name VF12: '3. BASE VARIABLES'!$F$39:$F$1416
Name VF18: '3. BASE VARIABLES'!$F$1474:$F$1478
Name VF2: '3. BASE VARIABLES'!$F$1482:$F$1492
Name VF4: '3. BASE VARIABLES'!$F$1783:$F$2041
Name VF5: '3. BASE VARIABLES'!$F$2042:$F$2300
Name VF6: '3. BASE VARIABLES'!$F$2301:$F$2559
Name VF7: '3. BASE VARIABLES'!$F$2560:$F$2592
Name VFF1: '3. BASE VARIABLES'!$F$2635:$F$2642
Name VFF2: '3. BASE VARIABLES'!$F$2643:$F$2647
Name VFF3: '3. BASE VARIABLES'!$F$2648:$F$2652
Name VFF4: '3. BASE VARIABLES'!$F$2653:$F$2656
Name VFF5: '3. BASE VARIABLES'!$F$2657:$F$2660
Name VFF6: '3. BASE VARIABLES'!$F$2661:$F$2663
Name VFF7: '3. BASE VARIABLES'!$F$2664:$F$2667
Name VFF8: '3. BASE VARIABLES'!$F$2668:$F$2670
Name VFF9: '3. BASE VARIABLES'!$F$2671:$F$2673

Sheet CAMBIOS v2.6
A1: MATRIZ DE RIESGO FIDEICOMISOS · CAMBIOS v2.5 → v2.6 (21-oct-2026)
A2: Recoge los acuerdos de las sesiones del 8 y 16 de octubre. Las hojas nuevas son FUENTES DE DATOS, INVALIDACIONES y LISTAS.
A4: Factor | B4: Nombre | C4: Peso v2.5 | D4: Peso v2.6 | E4: Por qué
A5: FF1 | B5: Tipo de fideicomiso | C5: 16 | D5: 30 | E5: Se conserva: tipo de la Cartera Fids de BX+ y de los expedientes. Nueva opción: administración inmobiliaria (nivel 3)
A6: FF4 | B6: Antigüedad del fideicomiso | C6: 7 | D6: 13 | E6: Existe en las bases
A7: FF6 | B7: Actividad vulnerable LFPIORPI | C7: 14 | D7: 27 | E7: Base de expedientes + validación de BX+
A8: FF7 | B8: Procedencia de los recursos | C8: 10 | D8: 19 | E8: Existe en la Base SharePoint
A9: FF8 | B9: Operaciones en USD / transfronterizas | C9: 6 | D9: 11 | E9: Existe en la Base SharePoint
A10: FF2 | B10: Patrimonio aportado | C10: 10 | D10: 0 | E10: Segunda fase: no está en las bases
A11: FF3 | B11: Valor del patrimonio | C11: 11 | D11: 0 | E11: Segunda fase: no está en las bases
A12: FF5 | B12: Número de partes | C12: 9 | D12: 0 | E12: Segunda fase: sólo existe en la base de expedientes (376)
A13: FF9 | B13: Operación distinta al fin del contrato | C13: 5 | D13: 0 | E13: Segunda fase: requiere monitoreo
A14: FF10 | B14: Ubicación del patrimonio | C14: 12 | D14: 0 | E14: Segunda fase: no está en las bases
B15: TOTAL DEL VEHÍCULO | C15: 100 | D15: 100 | E15: Los 53 puntos de los factores que quedan se llevaron a 100 en proporción
A18: OTROS CAMBIOS
A19: • Riesgo heredado del banco como piso del consolidado (el mayor entre Base SharePoint y SIPREV).
A20: • Se elimina la marca «S» del campo de listas. Las invalidaciones por listas se mantienen (hoja INVALIDACIONES).
A21: • Nueva invalidación A8: investigación del integrante (noticias negativas, buró legal y fiscal), captura manual.
A22: • Actividad vulnerable: las fracciones V y V Bis se registran por separado en la base de carga.
A23: • CALIFICACIÓN FINAL = consolidado con invalidaciones (prohibitiva 500; alto riesgo mínimo 291), en el modelo de ejemplo y en la captura masiva.
A24: • Bloque B (integrantes) y bandas de la Tabla 5 sin cambio.
A25: DECISIONES PENDIENTES (Maribel / BX+)
A26: 1. Nivel de la nueva opción «administración inmobiliaria» en FF1 (propuesto 3).
A27: 2. Actividad vulnerable de la base de expedientes: desarrollo inmobiliario como confirmada (5) y arrendamiento como potencial (3) hasta verificar el umbral.
A28: 3. Dato faltante: se mantiene NO DETERMINADO = 2.58 (regla del 24-sep). Efecto: un fideicomiso sin datos queda en MEDIO aunque el banco lo tenga en BAJO. Alternativa: tomar el riesgo heredado como único criterio cuando falten datos.
A29: 4. Criterio de calificación única Banco–Fiduciario: propuesta enviada el 21-oct (prevalece la más alta).
... A35: • Fuentes cargadas: base conciliada, expedientes (376), Cartera Fids de BX+ al 08-oct (1,190) e inferencia de AV en espera de la validación de BX+.

Sheet GUÍA DE USO
B2: LEX QUO · MATRIZ DE RIESGO DE FIDEICOMISOS v2.6 — espejo del modelo de clientes BX+
B4: Flujo de operación (idéntico en lógica al modelo del banco)
B5: 1 · 3. BASE VARIABLES | C5: Copiada TAL CUAL del modelo de clientes BX+ (2,628 variables con sus claves, probabilidades y multiplicadores — ya viven en el sistema). Al final se agregaron 39 variables fiduciarias nuevas (serie de claves 9000) con la misma lógica: PUNTAJE = PROBABILIDAD × MULTIPLICADOR.
B6: 2 · MODELO EJEMPLO FID | C6: Motor didáctico para UN fideicomiso: se capturan las variables del vehículo y de cada integrante, y se ve el cálculo completo hasta el riesgo consolidado. Escala 100–500 y bandas de la Tabla 5 de la Matriz BX+ (grado de riesgo de cliente — NO la escala de la Guía CNBV, que aplica al EBR de la entidad) (100–223 BAJO · 224–258 MEDIO · 259–290 MEDIO ALTO · 291–500 ALTO).
B7: 3 · CAPTURA INTEGRANTES | C7: Una LÍNEA POR PARTE (como el banco captura una línea por cuenta): ID del fideicomiso, rol y los 7 factores personales (niveles 1–5 según la base de variables). Calcula el riesgo de cada integrante y su aporte ponderado por rol.
B8: 4 · BASE DE CARGA | C8: Una fila por fideicomiso con las columnas del LAYOUT DE CARGA, tal como salen del sistema del banco (claves ZCALIFICA, ZVALF0011, ZVALF0021…, textos de tipo y producto). Cada valor se traduce a su nivel buscando la clave en la columna G de 3. BASE VARIABLES (procedencia) o en EQUIVALENCIAS. La columna Y de la base de variables dice qué clave del banco corresponde a cada variable. El mismo archivo se carga en la aplicación v2.0.
B9: 5 · MATRIZ CONSOLIDADA | C9: Estadística de TODA la base por fórmulas (COUNTIFS): distribución por banda, prohibitivos, invalidaciones y promedio.
B11: Reglas de consolidación e invalidaciones
B12: Consolidado | C12: CONSOLIDADO = el mayor entre riesgo heredado del banco, estructural del vehículo y promedio ponderado de integrantes; si la peor parte es ALTO (≥291), el fideicomiso no baja de ella. Después se aplican las invalidaciones: prohibitiva → 500; de alto riesgo → mínimo 291. Pesos de rol: fideicomitente 40% · fideicomisario 25% · comité técnico 20% · apoderado 15% (normalizados).
B13: Invalidaciones (cascada del banco) | C13: Ver hoja INVALIDACIONES: B1–B3 prohibitivas (no se opera) y A1–A8 de alto riesgo (requieren aprobación de nivel directivo). La marca «S» del campo de listas de la Base SharePoint ya no se usa.
B14: Pesos por factor | C14: Fideicomiso (suma 100, v2.6): FF1 tipo de fideicomiso 30 · FF4 antigüedad 13 · FF6 actividad vulnerable 27 · FF7 procedencia 19 · FF8 USD 11. Segunda fase (peso 0): FF2 patrimonio, FF3 valor, FF5 número de partes, FF9 operación distinta al fin, FF10 ubicación. FF11 giro no pondera (dispara TR-23). Integrante (suma 100): FI1 15 · FI2 23 · FI3 9 · FI4 11 · FI5 11 · FI6 12 · FI7 7 · FI8 rol 12. Ruta heredada del integrante que ya es cliente del banco: nivel del banco 80 + rol 20, con piso en el puntaje del banco. ACTUALIZADO 21-OCT-2026.
B16: Multiplicador vs. ponderación — propuesta para el sistema nuevo
B17: Equivalencia | C17: El MULTIPLICADOR del banco es el peso del factor expresado como entero (mult = peso% × 100): nivel×multiplicador ≡ nivel×peso%. Por eso hoy cada factor queda en escala distinta (7–35, 8–40…). Para el SISTEMA NUEVO se propone: capturar todas las variables en escala uniforme 1–5 y ponderar con la tabla de PESOS % (columna R de 3. BASE VARIABLES) — mismo resultado numérico, pero con la escala y el peso como procesos separados, principio de separación escala/peso (buena práctica alineada a la Guía CNBV del EBR). La columna MULTIPLICADOR se conserva por compatibilidad con la operación actual del banco.
B19: Alcance del instrumento
B20: Cliente ≠ EBR | C20: Esta matriz determina el GRADO DE RIESGO DE CADA CLIENTE (fideicomiso y sus integrantes), conforme a las Disposiciones (clasificación por grado de riesgo). Es un instrumento DISTINTO E INDEPENDIENTE de la Metodología de Evaluación de Riesgos (MEBR/EBR de la entidad): la escala y bandas aquí usadas provienen de la Tabla 5 de la Matriz de Riesgo BX+ (modelo de clientes), no de la escala de la Guía CNBV, que aplica al EBR de la entidad.
A22: ACTUALIZACIÓN 28-AGO-2026: el Bloque B (integrantes) del MODELO EJEMPLO usa ahora los CATÁLOGOS OPERATIVOS V1 (final de la hoja 3. BASE VARIABLES, serie 9100), idénticos a las listas de la aplicación web, para que Excel y aplicación den el mismo resultado. Los catálogos completos del banco se conservan en la misma hoja como referencia y trazabilidad; la homologación fina (p. ej. mapear cada actividad del catálogo banco a su categoría operativa) queda para V2. | ACTUALIZACIÓN 5-SEP-2026: se renombró TIPOLOGÍA DEL FIDEICOMISO a TIPO DE FIDEICOMISO (en PLD/FT "tipología" designa un patrón de lavado; usarlo para la figura jurídica del contrato inducía a error). Se repesó el Bloque A a 10 factores con la ubicación del patrimonio, se incorporaron los pesos del Bloque B a la base, y se agregaron los catálogos de giro del fideicomiso y de nivel heredado del banco.

Sheet FUENTES DE DATOS
A1: FUENTES DE DATOS — de qué base sale cada factor para la carga
A2: Universo: base conciliada por fideicomiso (1,205 registros). Base de expedientes: Base_Fiduciaria (Ana Lilia, 8-oct), 376 coinciden. Cartera Fids (BX+, 08-oct): 1,610 fideicomisos activos, 1,190 coinciden.
A4: Factor | B4: Peso | C4: Fuente principal | D4: Cobertura | E4: Respaldo / regla cuando no hay dato | F4: Estado
A5: Riesgo heredado del banco | B5: Piso | C5: Base conciliada: banda Base SharePoint (equivalencia CAT) y nivel SIPREV, el mayor | D5: 1,205 de 1,205 | E5: — | F5: Listo
A6: FF1 Tipo de fideicomiso | B6: 30 | C6: Base de expedientes: tipo y subtipo (376, distingue inmobiliario) | D6: 376 | E6: Cartera Fids (BX+, 08-oct): tipo y producto (814 más). Si es mixto, se toma el de mayor nivel. Sin dato: NO DETERMINADO (2.58) | F6: Listo (15 sin dato)
A7: FF4 Antigüedad | B7: 13 | C7: Base de expedientes: fecha de constitución | D7: 376 | E7: Cartera Fids: fecha de constitución (resto). Último recurso: Base SharePoint campo 0020 | F7: Listo
A8: FF6 Actividad vulnerable | B8: 27 | C8: Base de expedientes: actividad vulnerable identificada (284 de 376 con AV) | D8: 376 | E8: Validación BX+ de los 34 inferidos (22-oct). Desarrollo inmobiliario → confirmada (5); sólo arrendamiento → potencial (3) hasta verificar el umbral de 1,605 UMA. Sin dato: NO DETERMINADO (2.58) | F8: Criterio a validar con BX+
A9: FF7 Procedencia de los recursos | B9: 19 | C9: Base SharePoint (factor F8 del modelo del banco) | D9: Todos | E9: — | F9: Listo
A10: FF8 Operaciones en USD / transfronterizas | B10: 11 | C10: Base SharePoint (factores F24 y F26) | D10: Todos | E10: — | F10: Listo
A11: Invalidaciones | B11: — | C11: Base SharePoint (listas sin la «S», PEP, actividad determinante) + captura manual A8 | D11: Todos | E11: — | F11: Listo
A12: Segunda fase: FF2, FF3, FF5, FF9, FF10 | B12: 0 | C12: Contrato / captura en la apertura | D12: — | E12: Número de partes (FF5) ya existe en la base de expedientes para 376; se puede activar cuando se amplíe la cobertura | F12: Segunda fase

Sheet LAYOUT DE CARGA
A1: LAYOUT DE CARGA v2.0 — una fila por fideicomiso, con los valores tal como salen del sistema del banco
A2: Archivo CSV (UTF-8) con estos encabezados. Si un fideicomiso tiene varias cuentas, puede venir en varias filas: la aplicación toma el valor de mayor riesgo de cada campo. Columnas extra se ignoran.
A4: Columna | B4: Fuente en el banco | C4: Contenido | D4: Ejemplo | E4: Alimenta
A5: NUM_FIDEICOMISO | B5: Cartera Fids | C5: Número de fideicomiso | D5: 1317 | E5: Obligatorio
A6: NOMBRE_FIDEICOMISO | B6: Cartera Fids | C6: Nombre | D6: PROMOCIONES INDUSTRIALES QUERÉTARO | E6: Opcional
A7: TIPO | B7: Cartera Fids («Tipo») | C7: Tipo de fideicomiso del sistema | D7: Administración | E7: FF1
A8: PRODUCTO | B8: Cartera Fids («Producto») | C8: Producto del sistema | D8: Fideicomiso de Administración | E8: FF1
A9: SUBTIPO_EXPEDIENTE | B9: Expediente (cédula) | C9: Subtipo de la cédula | D9: Inmobiliario | E9: FF1
A10: FECHA_CONSTITUCION | B10: Cartera Fids / campo 0020 | C10: dd/mm/aaaa o aaaammdd | D10: 23/02/2015 | E10: FF4
A11: ACTIVIDAD_VULNERABLE | B11: Cartera Fids / expediente / validación | C11: Texto de la actividad vulnerable | D11: Desarrollo Inmobiliario | E11: FF6
A12: ZCALIFICA | B12: Base SharePoint /BIC/ZCALIFICA | C12: Calificación del modelo del banco (A, B, C) | D12: A | E12: Riesgo heredado
A13: NIVEL_SIPREV | B13: SIPREV | C13: Nivel de riesgo del cliente | D13: MEDIO | E13: Riesgo heredado
A14: ZVALF0011_PROCEDENCIA | B14: Base SharePoint /BIC/ZVALF0011 | C14: Clave de procedencia (factor F8) | D14: IN | E14: FF7
A15: ZVALF0021_MONEDA | B15: Base SharePoint /BIC/ZVALF0021 | C15: Moneda de la cuenta | D15: MXN | E15: FF8
... A20: ORIGEN_TIPO / ORIGEN_FECHA / ORIGEN_AV | B20: Lex Quo | C20: Traza de la fuente; no se calcula | D20: Cartera Fids | E20: —

Sheet BASE DE CARGA
A1: BASE DE CARGA — los fideicomisos tal como los da el sistema del banco, traducidos y calificados
A2: Gris: columnas del LAYOUT DE CARGA (mismos nombres de campo del banco; es el mismo archivo que se carga en la aplicación). Azul: traducción automática. Blanco: cálculo. Para recargar, pegue debajo del renglón 5 las columnas A a R.
A3: PLANTILLA SIN DATOS DE CLIENTES: un renglón de ejemplo. Pegue debajo los fideicomisos del layout.
A4: LAYOUT DE CARGA — TAL COMO VIENE DEL BANCO | P4: TRAZA (no se calcula) | S4: TRADUCIDO CON LA BASE DE VARIABLES | AB4: CÁLCULO
A5: NUM_FIDEICOMISO | B5: NOMBRE_FIDEICOMISO | C5: TIPO | D5: PRODUCTO | E5: SUBTIPO_EXPEDIENTE | F5: FECHA_CONSTITUCION | G5: ACTIVIDAD_VULNERABLE | H5: ZCALIFICA | I5: NIVEL_SIPREV | J5: ZVALF0011_PROCEDENCIA | K5: ZVALF0021_MONEDA | L5: ZVALF0004_PEP | M5: ZVALF0023_REPORTES_PREVIOS | N5: INVESTIGACION_ADVERSA | O5: INVALIDACION_PROHIBITIVA | P5: ORIGEN_TIPO | Q5: ORIGEN_FECHA | R5: ORIGEN_AV | S5: Heredado · puntaje | T5: FF1 Tipo · variable | U5: FF1 · nivel | V5: FF4 · años | W5: FF4 · nivel | X5: FF6 AV · variable | Y5: FF6 · nivel | Z5: FF7 · nivel (F8 del banco) | AA5: FF8 · nivel | AB5: Estructural | AC5: Consolidado | AD5: Invalidación | AE5: Calificación final | AF5: Banda
A6: 1317 | B6: EJEMPLO SA | C6: Administración | D6: Fideicomiso de Administración | E6: Inmobiliario | F6: 23/02/2015 | G6: Desarrollo Inmobiliario | H6: A | I6: MEDIO | J6: IN | K6: MXN | L6: N | M6: NO | N6: NO | O6: NO | P6: Ejemplo | Q6: Ejemplo | R6: Ejemplo | S6: =MAX(IFERROR(VLOOKUP(H6,EQUIVALENCIAS!$A$5:$B$7,2,0),0),IFERROR(VLOOKUP(I6,EQUIVALENCIAS!$A$10:$B$14,2,0),0)) | T6: =IFERROR(VLOOKUP(C6&" | "&D6&" | "&E6,EQUIVALENCIAS!$E$5:$F$64,2,0),"NO DETERMINADO") | U6: =IFERROR(INDEX(LISTAS!$B$5:$B$14,MATCH(T6,LISTAS!$A$5:$A$14,0)),2.58) | V6: =IF(F6="","",ROUND((EQUIVALENCIAS!$B$16-IF(LEN(F6)=8,DATE(LEFT(F6,4),MID(F6,5,2),RIGHT(F6,2)),DATE(RIGHT(F6,4),MID(F6,4,2),LEFT(F6,2))))/365.25,2)) | W6: =IF(V6="",2.58,IF(V6<1,5,IF(V6<3,4,IF(V6<=10,2,1)))) | X6: =IFERROR(VLOOKUP(G6,EQUIVALENCIAS!$I$5:$J$18,2,0),"NO DETERMINADO") | Y6: =IFERROR(INDEX(LISTAS!$H$5:$H$8,MATCH(X6,LISTAS!$G$5:$G$8,0)),2.58) | Z6: =IFERROR(INDEX('3. BASE VARIABLES'!$H$2593:$H$2618,MATCH(J6,'3. BASE VARIABLES'!$G$2593:$G$2618,0)),2.58) | AA6: =IFERROR(VLOOKUP(K6,EQUIVALENCIAS!$A$19:$C$22,3,0),2.58) | AB6: =ROUND(U6*30+W6*13+Y6*27+Z6*19+AA6*11,0) | AC6: =MAX(S6,AB6) | AD6: =IF(UPPER(O6)="SI","B",IF(OR(UPPER(L6)="S",UPPER(M6)="SI",UPPER(N6)="SI"),"A","")) | AE6: =IF(AD6="B",500,IF(AD6="A",MAX(AC6,291),AC6)) | AF6: =IF(AE6>=500,"PROHIBITIVO",IF(AE6>=291,"ALTO",IF(AE6>=259,"MEDIO ALTO",IF(AE6>=224,"MEDIO","BAJO"))))

Sheet EQUIVALENCIAS
A1: EQUIVALENCIAS — cómo se traduce cada valor del banco a una variable de la matriz
A2: Los mismos criterios están programados en la aplicación v2.0. La procedencia (ZVALF0011) se busca directo en la columna G de 3. BASE VARIABLES. Celdas azules: criterio editable.
A4: ZCALIFICA (Base SharePoint) | B4: Puntaje heredado | E4: TIPO | PRODUCTO | SUBTIPO_EXPEDIENTE (como llega) | F4: Variable FF1 asignada | G4: Nivel | I4: ACTIVIDAD_VULNERABLE (como llega) | J4: Variable FF6 asignada | K4: Nivel
A5: A | B5: 162 | E5: | | | F5: NO DETERMINADO | G5: =IFERROR(INDEX(LISTAS!$B$5:$B$14,MATCH(F5,LISTAS!$A$5:$A$14,0)),2.58) | I5: Arrendamiento | J5: AV POTENCIAL / EN DICTAMEN (TIPO C) | K5: =IFERROR(INDEX(LISTAS!$H$5:$H$8,MATCH(J5,LISTAS!$G$5:$G$8,0)),2.58)
A6: B | B6: 241 | E6: Administación, Garantía y Fuente de Pago | Fideicomiso de Garantía | Inmobiliario | F6: FIDEICOMISO DE ADMINISTRACIÓN INMOBILIARIA (DESARROLLO O ARRENDAMIENTO) | G6: =IFERROR(INDEX(LISTAS!$B$5:$B$14,MATCH(F6,LISTAS!$A$5:$A$14,0)),2.58) | I6: Arrendamiento y desarrollo inmobiliario | J6: AV CONFIRMADA ART. 17 (TIPO B) | K6: =IFERROR(INDEX(LISTAS!$H$5:$H$8,MATCH(J6,LISTAS!$G$5:$G$8,0)),2.58)
A7: C | B7: 330 | E7: Administración e Inversión | Fideicomiso de Administración | Inmobiliario | F7: FIDEICOMISO DE ADMINISTRACIÓN INMOBILIARIA (DESARROLLO O ARRENDAMIENTO) | G7: =IFERROR(INDEX(LISTAS!$B$5:$B$14,MATCH(F7,LISTAS!$A$5:$A$14,0)),2.58) | I7: Dearrollo Inmobiliario y Arrendamiento | J7: AV CONFIRMADA ART. 17 (TIPO B) | K7: =IFERROR(INDEX(LISTAS!$H$5:$H$8,MATCH(J7,LISTAS!$G$5:$G$8,0)),2.58)
E8: Administración y Fuente de Pago | Fideicomiso de Administración | Patrimonial | F8: FIDEICOMISO FUENTE DE PAGO | G8: =IFERROR(INDEX(LISTAS!$B$5:$B$14,MATCH(F8,LISTAS!$A$5:$A$14,0)),2.58) | I8: Desarrollo Inmobiliario | J8: AV CONFIRMADA ART. 17 (TIPO B) | K8: =IFERROR(INDEX(LISTAS!$H$5:$H$8,MATCH(J8,LISTAS!$G$5:$G$8,0)),2.58)
A9: NIVEL_SIPREV | B9: Puntaje heredado | E9: Administración y Fuente de Pago | Fuente de Pago | Patrimonial | F9: FIDEICOMISO FUENTE DE PAGO | G9: =IFERROR(INDEX(LISTAS!$B$5:$B$14,MATCH(F9,LISTAS!$A$5:$A$14,0)),2.58) | I9: Desarrollo Inmobiliario y Aarrendamiento | J9: AV CONFIRMADA ART. 17 (TIPO B) | K9: =IFERROR(INDEX(LISTAS!$H$5:$H$8,MATCH(J9,LISTAS!$G$5:$G$8,0)),2.58)
A10: BAJO | B10: 162 | E10: Administración y Fuente de Pago | Fuente/Alterna de Pago | Garantía | F10: FIDEICOMISO FUENTE DE PAGO | G10: =IFERROR(INDEX(LISTAS!$B$5:$B$14,MATCH(F10,LISTAS!$A$5:$A$14,0)),2.58) | I10: Desarrollo Inmobiliario y Arrendamiento | J10: AV CONFIRMADA ART. 17 (TIPO B) | K10: =IFERROR(INDEX(LISTAS!$H$5:$H$8,MATCH(J10,LISTAS!$G$5:$G$8,0)),2.58)
A11: MEDIO | B11: 241 | E11: Administración y Garantía | Fideicomiso de Garantía | Inmobiliario | F11: FIDEICOMISO DE ADMINISTRACIÓN INMOBILIARIA (DESARROLLO O ARRENDAMIENTO) | G11: =IFERROR(INDEX(LISTAS!$B$5:$B$14,MATCH(F11,LISTAS!$A$5:$A$14,0)),2.58) | I11: Desarrollo Inmobiliario y arrendamiento | J11: AV CONFIRMADA ART. 17 (TIPO B) | K11: =IFERROR(INDEX(LISTAS!$H$5:$H$8,MATCH(J11,LISTAS!$G$5:$G$8,0)),2.58)
A12: MEDIO ALTO | B12: 275 | E12: Administración y Medio de Pago | Fuente/Alterna de Pago | Patrimonial | F12: FIDEICOMISO FUENTE DE PAGO | G12: =IFERROR(INDEX(LISTAS!$B$5:$B$14,MATCH(F12,LISTAS!$A$5:$A$14,0)),2.58) | I12: Inferida: Indicio | J12: AV POTENCIAL / EN DICTAMEN (TIPO C) | K12: =IFERROR(INDEX(LISTAS!$H$5:$H$8,MATCH(J12,LISTAS!$G$5:$G$8,0)),2.58)
A13: ALTO | B13: 330 | E13: Administración | | Inversión | F13: FIDEICOMISO DE INVERSIÓN | G13: =IFERROR(INDEX(LISTAS!$B$5:$B$14,MATCH(F13,LISTAS!$A$5:$A$14,0)),2.58) | I13: Inferida: No probable | J13: SIN ACTIVIDAD VULNERABLE (TIPO A) | K13: =IFERROR(INDEX(LISTAS!$H$5:$H$8,MATCH(J13,LISTAS!$G$5:$G$8,0)),2.58)
A14: ALTO RIESGO (INVALIDACION TIPO A) | B14: 330 | E14: Administración | Fideicomiso de Administración | | F14: FIDEICOMISO DE ADMINISTRACIÓN | G14: =IFERROR(INDEX(LISTAS!$B$5:$B$14,MATCH(F14,LISTAS!$A$5:$A$14,0)),2.58) | I14: Inferida: Sin elementos | J14: NO DETERMINADO | K14: =IFERROR(INDEX(LISTAS!$H$5:$H$8,MATCH(J14,LISTAS!$G$5:$G$8,0)),2.58)
E15: Administración | Fideicomiso de Administración | Fuente de Pago | F15: FIDEICOMISO FUENTE DE PAGO | G15: =IFERROR(INDEX(LISTAS!$B$5:$B$14,MATCH(F15,LISTAS!$A$5:$A$14,0)),2.58) | I15: Inferida: Sí probable | J15: AV POTENCIAL / EN DICTAMEN (TIPO C) | K15: =IFERROR(INDEX(LISTAS!$H$5:$H$8,MATCH(J15,LISTAS!$G$5:$G$8,0)),2.58)
A16: Fecha de corte (antigüedad): | B16: =TODAY() | E16: Administración | Fideicomiso de Administración | Garantía | F16: FIDEICOMISO DE GARANTÍA | G16: =IFERROR(INDEX(LISTAS!$B$5:$B$14,MATCH(F16,LISTAS!$A$5:$A$14,0)),2.58) | I16: No | J16: SIN ACTIVIDAD VULNERABLE (TIPO A) | K16: =IFERROR(INDEX(LISTAS!$H$5:$H$8,MATCH(J16,LISTAS!$G$5:$G$8,0)),2.58)
E17: Administración | Fideicomiso de Administración | Garantía e Inmobiliario | F17: FIDEICOMISO DE ADMINISTRACIÓN INMOBILIARIA (DESARROLLO O ARRENDAMIENTO) | G17: =IFERROR(INDEX(LISTAS!$B$5:$B$14,MATCH(F17,LISTAS!$A$5:$A$14,0)),2.58) | I17: Revisar | J17: AV POTENCIAL / EN DICTAMEN (TIPO C) | K17: =IFERROR(INDEX(LISTAS!$H$5:$H$8,MATCH(J17,LISTAS!$G$5:$G$8,0)),2.58)
A18: ZVALF0021_MONEDA | B18: Variable FF8 | C18: Nivel | E18: Administración | Fideicomiso de Administración | Garantía y Fuente de Pago | F18: FIDEICOMISO FUENTE DE PAGO | G18: =IFERROR(INDEX(LISTAS!$B$5:$B$14,MATCH(F18,LISTAS!$A$5:$A$14,0)),2.58) | I18: Sin AV en expediente | J18: SIN ACTIVIDAD VULNERABLE (TIPO A) | K18: =IFERROR(INDEX(LISTAS!$H$5:$H$8,MATCH(J18,LISTAS!$G$5:$G$8,0)),2.58)
A19: MXN | B19: SIN OPERACIONES USD NI EXTRANJERO | C19: =IFERROR(INDEX(LISTAS!$N$5:$N$8,MATCH(B19,LISTAS!$M$5:$M$8,0)),2.58) | E19: Administración | Fideicomiso de Administración | Inmobiliario | F19: FIDEICOMISO DE ADMINISTRACIÓN INMOBILIARIA (DESARROLLO O ARRENDAMIENTO) | G19: =IFERROR(INDEX(LISTAS!$B$5:$B$14,MATCH(F19,LISTAS!$A$5:$A$14,0)),2.58)
A20: USD | B20: USD OCASIONAL / PARTE EXTRANJERA | C20: =IFERROR(INDEX(LISTAS!$N$5:$N$8,MATCH(B20,LISTAS!$M$5:$M$8,0)),2.58) | E20: Administración | Fideicomiso de Administración | Inmobiliario y Patrimonial | F20: FIDEICOMISO DE ADMINISTRACIÓN INMOBILIARIA (DESARROLLO O ARRENDAMIENTO) | G20: =IFERROR(INDEX(LISTAS!$B$5:$B$14,MATCH(F20,LISTAS!$A$5:$A$14,0)),2.58)
A21: EUR | B21: USD OCASIONAL / PARTE EXTRANJERA | C21: =IFERROR(INDEX(LISTAS!$N$5:$N$8,MATCH(B21,LISTAS!$M$5:$M$8,0)),2.58) | E21: Administración | Fideicomiso de Administración | Inversión | F21: FIDEICOMISO DE INVERSIÓN | G21: =IFERROR(INDEX(LISTAS!$B$5:$B$14,MATCH(F21,LISTAS!$A$5:$A$14,0)),2.58)
A22: CAD | B22: USD OCASIONAL / PARTE EXTRANJERA | C22: =IFERROR(INDEX(LISTAS!$N$5:$N$8,MATCH(B22,LISTAS!$M$5:$M$8,0)),2.58) | E22: Administración | Fideicomiso de Administración | Inversión - Previsión social | F22: FIDEICOMISO DE INVERSIÓN | G22: =IFERROR(INDEX(LISTAS!$B$5:$B$14,MATCH(F22,LISTAS!$A$5:$A$14,0)),2.58)
E23: Administración | Fideicomiso de Administración | Inversión y Patrimonial | F23: FIDEICOMISO DE INVERSIÓN | G23: =IFERROR(INDEX(LISTAS!$B$5:$B$14,MATCH(F23,LISTAS!$A$5:$A$14,0)),2.58)
E24: Administración | Fideicomiso de Administración | Medio de Pago | F24: FIDEICOMISO FUENTE DE PAGO | G24: =IFERROR(INDEX(LISTAS!$B$5:$B$14,MATCH(F24,LISTAS!$A$5:$A$14,0)),2.58)
E25: Administración | Fideicomiso de Administración | Patrimonial | F25: FIDEICOMISO TESTAMENTARIO / PLANEACIÓN PATRIMONIAL | G25: =IFERROR(INDEX(LISTAS!$B$5:$B$14,MATCH(F25,LISTAS!$A$5:$A$14,0)),2.58)
E26: Administración | Fideicomiso de Administración | Patrimonial Testamentario | F26: FIDEICOMISO TESTAMENTARIO / PLANEACIÓN PATRIMONIAL | G26: =IFERROR(INDEX(LISTAS!$B$5:$B$14,MATCH(F26,LISTAS!$A$5:$A$14,0)),2.58)
E27: Administración | Fideicomiso de Administración | Patrimonial e Inmobiliario | F27: FIDEICOMISO DE ADMINISTRACIÓN INMOBILIARIA (DESARROLLO O ARRENDAMIENTO) | G27: =IFERROR(INDEX(LISTAS!$B$5:$B$14,MATCH(F27,LISTAS!$A$5:$A$14,0)),2.58)
E28: Administración | Fideicomiso de Administración | Patrimonial e Inversión | F28: FIDEICOMISO DE INVERSIÓN | G28: =IFERROR(INDEX(LISTAS!$B$5:$B$14,MATCH(F28,LISTAS!$A$5:$A$14,0)),2.58)
E29: Administración | Fideicomiso de Administración | Patrimonial y Testamentario | F29: FIDEICOMISO TESTAMENTARIO / PLANEACIÓN PATRIMONIAL | G29: =IFERROR(INDEX(LISTAS!$B$5:$B$14,MATCH(F29,LISTAS!$A$5:$A$14,0)),2.58)
E30: Administración | Fideicomiso de Administración | Patrimonial y Testamentatio | F30: FIDEICOMISO TESTAMENTARIO / PLANEACIÓN PATRIMONIAL | G30: =IFERROR(INDEX(LISTAS!$B$5:$B$14,MATCH(F30,LISTAS!$A$5:$A$14,0)),2.58)
E31: Administración | Fideicomiso de Administración | Testamentario y Patrimonial | F31: FIDEICOMISO TESTAMENTARIO / PLANEACIÓN PATRIMONIAL | G31: =IFERROR(INDEX(LISTAS!$B$5:$B$14,MATCH(F31,LISTAS!$A$5:$A$14,0)),2.58)
E32: Administración | Fideicomiso de Garantía | | F32: FIDEICOMISO DE GARANTÍA | G32: =IFERROR(INDEX(LISTAS!$B$5:$B$14,MATCH(F32,LISTAS!$A$5:$A$14,0)),2.58)
E33: Administración | Fideicomiso de Garantía | Fuente de Pago | F33: FIDEICOMISO FUENTE DE PAGO | G33: =IFERROR(INDEX(LISTAS!$B$5:$B$14,MATCH(F33,LISTAS!$A$5:$A$14,0)),2.58)
E34: Administración | Fideicomiso de Garantía | Garantía | F34: FIDEICOMISO DE GARANTÍA | G34: =IFERROR(INDEX(LISTAS!$B$5:$B$14,MATCH(F34,LISTAS!$A$5:$A$14,0)),2.58)
... E64: Inversión | Fideicomiso de Inversión | | F64: FIDEICOMISO DE INVERSIÓN | G64: =IFERROR(INDEX(LISTAS!$B$5:$B$14,MATCH(F64,LISTAS!$A$5:$A$14,0)),2.58)
E66: Si llega un valor nuevo que no está en estas tablas, el Excel lo deja en NO DETERMINADO (2.58): agregue el renglón con su variable. La aplicación lo reconoce sola por palabras clave (inmobiliario, garantía, inversión, desarrollo, arrendamiento…).

Sheet INVALIDACIONES
A1: INVALIDACIONES — se aplican después de calcular el puntaje
A2: Prohibitiva: el fideicomiso queda en 500 (no se opera). Alto riesgo: mínimo 291 (ALTO), requiere aprobación de nivel directivo. Aplican si las tiene el fideicomiso o cualquiera de sus integrantes.
A4: Clave | B4: Tipo | C4: Invalidación | D4: Fuente / cómo se captura
A5: B1 | B5: Prohibitiva | C5: País en lista negra del GAFI (nacimiento, nacionalidad, domicilio o envío/recepción de transferencias) | D5: Modelo de clientes del banco (tablas F4–F6, F26)
A6: B2 | B6: Prohibitiva | C6: Actividad económica prohibida | D6: Catálogo de actividades del banco
A7: B3 | B7: Prohibitiva | C7: Coincidencia confirmada en lista de bloqueados o de sanciones | D7: Área de Cumplimiento
A8: A1 | B8: Alto riesgo | C8: PEP o familiar directo | D8: Expediente / modelo del banco
A9: A2 | B9: Alto riesgo | C9: Propietario real o beneficiario controlador no identificado (>25%) | D9: Expediente
A10: A3 | B10: Alto riesgo | C10: Cliente con reportes previos a la autoridad | D10: Área de Cumplimiento
A11: A4 | B11: Alto riesgo | C11: Coincidencia en lista de alto riesgo, de precaución o interna (distinta de bloqueados) | D11: Área de Cumplimiento
A12: A5 | B12: Alto riesgo | C12: País en jurisdicción gris del GAFI | D12: Modelo de clientes del banco
A13: A6 | B13: Alto riesgo | C13: Actividad económica determinante | D13: Catálogo de actividades del banco
A14: A7 | B14: Alto riesgo | C14: Entidad auxiliar del crédito (SOFOM, SOFIPO, SOFOL, arrendadora, aseguradora, transmisor, almacén). No aplica a bancos | D14: Política interna BX+
A15: A8 | B15: Alto riesgo | C15: NUEVA v2.6 · Resultado adverso de la investigación del integrante: noticias negativas, buró legal (litigios activos) o fiscal (créditos fiscales, incumplimientos) | D15: Captura manual tras la investigación (acuerdo del 8-oct)
A16: — | B16: Eliminada | C16: Marca «S» del campo de listas de la Base SharePoint (regla 211) | D16: Se elimina el 8-oct: BX+ no conoce su significado

Sheet 3. BASE VARIABLES
C2: CÓMO SE LLENA ESTA HOJA — Es una sola tabla. Use los filtros del renglón 4. 1) Filtre la columna BLOQUE por «A · VEHÍCULO» o «B · INTEGRANTE» según lo que quiera revisar. 2) Filtre la columna ORIGEN por «NUEVA» para ver únicamente lo que estamos proponiendo: son 75 renglones y es lo más importante. Lo demás ya viene del modelo del banco y no cambia. 3) Las dos últimas columnas, en AMARILLO, son suyas: elija de la lista y escriba el nombre o el grupo que debería tener. Las filas con fondo AZUL son variables nuevas del vehículo. Las de fondo GRIS son las nuevas del participante.
B3: TABLA 3. BASE VARIABLES DE FACTORES DE RIESGO CONGRUENTE CON METODOLOGIA
B4: Columna1 | C4: FACTOR O INDICADOR DE RIESGO | D4: FACTOR NUM. | E4: CARACTERISTICA DEL FACTOR O INDICADOR | F4: VARIABLES DE RIESGO | G4: CLAVE DEL BANCO (en su caso) | H4: PROBABILIDAD DE RIESGO DE LA VARIABLE (MEBR) PF | I4: PROBABILIDAD DE RIESGO DE LA VARIABLE (MEBR) PM | J4: MULTIPLICADOR | K4: PF | L4: PFAE | M4: PM | N4: FID | O4: MAX | P4: MIN | Q4: INVALIDACIONES | R4: PESO % (= MULT/100) | S4: ¿APLICA FID? | T4: BLOQUE | U4: ORIGEN DE LA VARIABLE | V4: GRUPO OPERATIVO FID (solo actividades) | W4: ▸ VALIDACIÓN BX+ | X4: ▸ NOMBRE O GRUPO PROPUESTO / COMENTARIO | Y4: ▸ CLAVE O VALOR EN EL SISTEMA DEL BANCO (cómo llega en el layout de carga)
C5: PRODUCTO | D5: F1 | E5: INHERENTE | F5: CUENTA SUELDOS Y SALARIOS CON INTERES | G5: 1001 | H5: 3 | I5: 3 | J5: 7 | K5: 21 | L5: 21 | M5: 21 | N5: 21 | O5: 35 | P5: 7 | R5: 0.07 | S5: NO — sustituido por FF1 (tipo de fideicomiso) | U5: DEL BANCO (se hereda)
C6: PRODUCTO | D6: F1 | E6: INHERENTE | F6: CUENTA SUELDOS Y SALARIOS SIN INTERES | G6: 1002 | H6: 3 | I6: 3 | J6: 7 | K6: 21 | L6: 21 | M6: 21 | N6: 21 | O6: 35 | P6: 7 | R6: 0.07 | S6: NO — sustituido por FF1 (tipo de fideicomiso) | U6: DEL BANCO (se hereda)
C7: PRODUCTO | D7: F1 | E7: INHERENTE | F7: CUENTA SIN CHEQUERA CON INTERESES (VERDE) | G7: 1003 | H7: 3 | I7: 3 | J7: 7 | K7: 21 | L7: 21 | M7: 21 | N7: 21 | O7: 35 | P7: 7 | R7: 0.07 | S7: NO — sustituido por FF1 (tipo de fideicomiso) | U7: DEL BANCO (se hereda)
C8: PRODUCTO | D8: F1 | E8: INHERENTE | F8: CUENTA SIN CHEQUERA SIN INTERESES (VISTA) | G8: 1004 | H8: 2 | I8: 2 | J8: 7 | K8: 14 | L8: 14 | M8: 14 | N8: 14 | O8: 35 | P8: 7 | R8: 0.07 | S8: NO — sustituido por FF1 (tipo de fideicomiso) | U8: DEL BANCO (se hereda)
C9: PRODUCTO | D9: F1 | E9: INHERENTE | F9: CUENTA CON CHEQUERA (BÁSICA CON Y SIN INTERES) | G9: 1007 | H9: 3 | I9: 3 | J9: 7 | K9: 21 | L9: 21 | M9: 21 | N9: 21 | O9: 35 | P9: 7 | R9: 0.07 | S9: NO — sustituido por FF1 (tipo de fideicomiso) | U9: DEL BANCO (se hereda)
C10: PRODUCTO | D10: F1 | E10: INHERENTE | F10: CTA. CON CHQ CON INT - SALARIOS | G10: 1008 | H10: 3 | I10: 3 | J10: 7 | K10: 21 | L10: 21 | M10: 21 | N10: 21 | O10: 35 | P10: 7 | R10: 0.07 | S10: NO — sustituido por FF1 (tipo de fideicomiso) | U10: DEL BANCO (se hereda)
C11: PRODUCTO | D11: F1 | E11: INHERENTE | F11: CTA CON INTERESES 360 | G11: 1010 | H11: 3 | I11: 3 | J11: 7 | K11: 21 | L11: 21 | M11: 21 | N11: 21 | O11: 35 | P11: 7 | R11: 0.07 | S11: NO — sustituido por FF1 (tipo de fideicomiso) | U11: DEL BANCO (se hereda)
C12: PRODUCTO | D12: F1 | E12: INHERENTE | F12: CUENTA BX+ BENEFICIOS PF/PFAE | G12: 1013 | H12: 3 | I12: 3 | J12: 7 | K12: 21 | L12: 21 | M12: 21 | N12: 21 | O12: 35 | P12: 7 | R12: 0.07 | S12: NO — sustituido por FF1 (tipo de fideicomiso) | U12: DEL BANCO (se hereda)
C13: PRODUCTO | D13: F1 | E13: INHERENTE | F13: CUENTA BX+ SERVICIOS PF/FAE | G13: 1014 | H13: 3 | I13: 3 | J13: 7 | K13: 21 | L13: 21 | M13: 21 | N13: 21 | O13: 35 | P13: 7 | R13: 0.07 | S13: NO — sustituido por FF1 (tipo de fideicomiso) | U13: DEL BANCO (se hereda)
C14: PRODUCTO | D14: F1 | E14: INHERENTE | F14: CUENTA BX+ USD PF (VISTA) | G14: 1015 | H14: 2 | I14: 2 | J14: 7 | K14: 14 | L14: 14 | M14: 14 | N14: 14 | O14: 35 | P14: 7 | R14: 0.07 | S14: NO — sustituido por FF1 (tipo de fideicomiso) | U14: DEL BANCO (se hereda)
C15: PRODUCTO | D15: F1 | E15: INHERENTE | F15: CUENTA BX+ EMPRESAS PM/FID | G15: 1016 | H15: 3 | I15: 3 | J15: 7 | K15: 21 | L15: 21 | M15: 21 | N15: 21 | O15: 35 | P15: 7 | R15: 0.07 | S15: NO — sustituido por FF1 (tipo de fideicomiso) | U15: DEL BANCO (se hereda)
C16: PRODUCTO | D16: F1 | E16: INHERENTE | F16: CUENTA BX+ EMPRESAS USD PM/FID | G16: 1017 | H16: 3 | I16: 3 | J16: 7 | K16: 21 | L16: 21 | M16: 21 | N16: 21 | O16: 35 | P16: 7 | R16: 0.07 | S16: NO — sustituido por FF1 (tipo de fideicomiso) | U16: DEL BANCO (se hereda)
... C38: PRODUCTO | D38: F1 | E38: INHERENTE | F38: CONTRATO DE CAMBIOS | G38: 999990 | H38: 1 | I38: 1 | J38: 7 | K38: 7 | L38: 7 | M38: 7 | N38: 7 | O38: 35 | P38: 7 | R38: 0.07 | S38: NO — sustituido por FF1 (tipo de fideicomiso) | U38: DEL BANCO (se hereda)
C39: Actividad económica / giro mercantil | D39: F12 | E39: INHERENTE | F39: SE DESCONOCE (TENTATIVA) | G39: 0 | H39: 5 | I39: 5 | J39: 8 | K39: 40 | L39: 40 | M39: 40 | N39: 40 | O39: 40 | P39: 8 | R39: 0.08 | S39: SÍ — integrante | T39: B · INTEGRANTE | U39: DEL BANCO (se hereda) | V39: 9116 · NO CAPTURADA
C40: Actividad económica / giro mercantil | D40: F12 | E40: INHERENTE | F40: AGRICULTURA | G40: 100008 | H40: 2 | I40: 2 | J40: 8 | K40: 16 | L40: 16 | M40: 16 | N40: 16 | O40: 40 | P40: 8 | R40: 0.08 | S40: SÍ — integrante | T40: B · INTEGRANTE | U40: DEL BANCO (se hereda) | V40: 9151 · SECTOR PRIMARIO (agropecuario, pesca, forestal, minería)
C41: Actividad económica / giro mercantil | D41: F12 | E41: INHERENTE | F41: 1.Agricultura | G41: 100101 | H41: 2 | I41: 2 | J41: 8 | K41: 16 | L41: 16 | M41: 16 | N41: 16 | O41: 40 | P41: 8 | R41: 0.08 | S41: SÍ — integrante | T41: B · INTEGRANTE | U41: DEL BANCO (se hereda) | V41: 9151 · SECTOR PRIMARIO (agropecuario, pesca, forestal, minería)
C42: Actividad económica / giro mercantil | D42: F12 | E42: INHERENTE | F42: 2. Ganadería | G42: 100102 | H42: 2 | I42: 2 | J42: 8 | K42: 16 | L42: 16 | M42: 16 | N42: 16 | O42: 40 | P42: 8 | R42: 0.08 | S42: SÍ — integrante | T42: B · INTEGRANTE | U42: DEL BANCO (se hereda) | V42: 9151 · SECTOR PRIMARIO (agropecuario, pesca, forestal, minería)
C43: Actividad económica / giro mercantil | D43: F12 | E43: INHERENTE | F43: Silvicultura | G43: 100103 | H43: 2 | I43: 2 | J43: 8 | K43: 16 | L43: 16 | M43: 16 | N43: 16 | O43: 40 | P43: 8 | R43: 0.08 | S43: SÍ — integrante | T43: B · INTEGRANTE | U43: DEL BANCO (se hereda) | V43: 9151 · SECTOR PRIMARIO (agropecuario, pesca, forestal, minería)
C44: Actividad económica / giro mercantil | D44: F12 | E44: INHERENTE | F44: Caza y pesca | G44: 100104 | H44: 2 | I44: 2 | J44: 8 | K44: 16 | L44: 16 | M44: 16 | N44: 16 | O44: 40 | P44: 8 | R44: 0.08 | S44: SÍ — integrante | T44: B · INTEGRANTE | U44: DEL BANCO (se hereda) | V44: 9151 · SECTOR PRIMARIO (agropecuario, pesca, forestal, minería)
C45: Actividad económica / giro mercantil | D45: F12 | E45: INHERENTE | F45: CULTIVO DE ALPISTE | G45: 111013 | H45: 2 | I45: 2 | J45: 8 | K45: 16 | L45: 16 | M45: 16 | N45: 16 | O45: 40 | P45: 8 | R45: 0.08 | S45: SÍ — integrante | T45: B · INTEGRANTE | U45: DEL BANCO (se hereda) | V45: 9151 · SECTOR PRIMARIO (agropecuario, pesca, forestal, minería)
C46: Actividad económica / giro mercantil | D46: F12 | E46: INHERENTE | F46: CULTIVO DE ARROZ | G46: 111021 | H46: 3 | I46: 3 | J46: 8 | K46: 24 | L46: 24 | M46: 24 | N46: 24 | O46: 40 | P46: 8 | R46: 0.08 | S46: SÍ — integrante | T46: B · INTEGRANTE | U46: DEL BANCO (se hereda) | V46: 9151 · SECTOR PRIMARIO (agropecuario, pesca, forestal, minería)
C47: Actividad económica / giro mercantil | D47: F12 | E47: INHERENTE | F47: CULTIVO DE AVENA | G47: 111039 | H47: 2 | I47: 2 | J47: 8 | K47: 16 | L47: 16 | M47: 16 | N47: 16 | O47: 40 | P47: 8 | R47: 0.08 | S47: SÍ — integrante | T47: B · INTEGRANTE | U47: DEL BANCO (se hereda) | V47: 9151 · SECTOR PRIMARIO (agropecuario, pesca, forestal, minería)
C48: Actividad económica / giro mercantil | D48: F12 | E48: INHERENTE | F48: CULTIVO DE CEBADA | G48: 111047 | H48: 2 | I48: 2 | J48: 8 | K48: 16 | L48: 16 | M48: 16 | N48: 16 | O48: 40 | P48: 8 | R48: 0.08 | S48: SÍ — integrante | T48: B · INTEGRANTE | U48: DEL BANCO (se hereda) | V48: 9151 · SECTOR PRIMARIO (agropecuario, pesca, forestal, minería)
C49: Actividad económica / giro mercantil | D49: F12 | E49: INHERENTE | F49: CULTIVO DE LINAZA | G49: 111055 | H49: 2 | I49: 2 | J49: 8 | K49: 16 | L49: 16 | M49: 16 | N49: 16 | O49: 40 | P49: 8 | R49: 0.08 | S49: SÍ — integrante | T49: B · INTEGRANTE | U49: DEL BANCO (se hereda) | V49: 9151 · SECTOR PRIMARIO (agropecuario, pesca, forestal, minería)
C50: Actividad económica / giro mercantil | D50: F12 | E50: INHERENTE | F50: CULTIVO DE MAIZ | G50: 111063 | H50: 2 | I50: 2 | J50: 8 | K50: 16 | L50: 16 | M50: 16 | N50: 16 | O50: 40 | P50: 8 | R50: 0.08 | S50: SÍ — integrante | T50: B · INTEGRANTE | U50: DEL BANCO (se hereda) | V50: 9151 · SECTOR PRIMARIO (agropecuario, pesca, forestal, minería)
... C166: Actividad económica / giro mercantil | D166: F12 | E166: INHERENTE | F166: Equipos y aparatos eléctricos | G166: 200955 | H166: 2 | I166: 2 | J166: 8 | K166: 16 | L166: 16 | M166: 16 | N166: 16 | O166: 40 | P166: 8 | R166: 0.08 | S166: SÍ — integrante | T166: B · INTEGRANTE | U166: DEL BANCO (se hereda) | V166: 9154 · OTRAS ACTIVIDADES NO CLASIFICADAS
C167: Actividad económica / giro mercantil | D167: F12 | E167: INHERENTE | F167: 56.Vehículos y automóviles | G167: 200956 | H167: 5 | I167: 5 | J167: 8 | K167: 40 | L167: 40 | M167: 40 | N167: 40 | O167: 40 | P167: 8 | Q167: DETERMINANTE | R167: 0.08 | S167: SÍ — integrante | T167: B · INTEGRANTE | U167: DEL BANCO (se hereda) | V167: 9154 · OTRAS ACTIVIDADES NO CLASIFICADAS
C168: Actividad económica / giro mercantil | D168: F12 | E168: INHERENTE | F168: Carrocerías, Motores, Partes y A | G168: 200957 | H168: 2 | I168: 2 | J168: 8 | K168: 16 | L168: 16 | M168: 16 | N168: 16 | O168: 40 | P168: 8 | R168: 0.08 | S168: SÍ — integrante | T168: B · INTEGRANTE | U168: DEL BANCO (se hereda) | V168: 9152 · INDUSTRIA Y MANUFACTURA
C169: Actividad económica / giro mercantil | D169: F12 | E169: INHERENTE | F169: 58.Equipos y materiales de transp. | G169: 200958 | H169: 1 | I169: 1 | J169: 8 | K169: 8 | L169: 8 | M169: 8 | N169: 8 | O169: 40 | P169: 8 | R169: 0.08 | S169: SÍ — integrante | T169: B · INTEGRANTE | U169: DEL BANCO (se hereda) | V169: 9154 · OTRAS ACTIVIDADES NO CLASIFICADAS
C170: Actividad económica / giro mercantil | D170: F12 | E170: INHERENTE | F170: FABRICACION DE ARMAS | G170: 200959 | H170: 5 | I170: 5 | J170: 8 | K170: 40 | L170: 40 | M170: 40 | N170: 40 | O170: 40 | P170: 8 | Q170: DETERMINANTE | R170: 0.08 | S170: SÍ — integrante | T170: B · INTEGRANTE | U170: DEL BANCO (se hereda) | V170: 9152 · INDUSTRIA Y MANUFACTURA
C171: Actividad económica / giro mercantil | D171: F12 | E171: INHERENTE | F171: 59.Otras ind. manufacturera | G171: 201059 | H171: 1 | I171: 1 | J171: 8 | K171: 8 | L171: 8 | M171: 8 | N171: 8 | O171: 40 | P171: 8 | R171: 0.08 | S171: SÍ — integrante | T171: B · INTEGRANTE | U171: DEL BANCO (se hereda) | V171: 9152 · INDUSTRIA Y MANUFACTURA
C172: Actividad económica / giro mercantil | D172: F12 | E172: INHERENTE | F172: 60.Construcción | G172: 201160 | H172: 5 | I172: 5 | J172: 8 | K172: 40 | L172: 40 | M172: 40 | N172: 40 | O172: 40 | P172: 8 | Q172: DETERMINANTE | R172: 0.08 | S172: SÍ — integrante | T172: B · INTEGRANTE | U172: DEL BANCO (se hereda) | V172: 9117 · INMOBILIARIO / CONSTRUCCIÓN
C173: Actividad económica / giro mercantil | D173: F12 | E173: INHERENTE | F173: 61. Electricidad, gas y agua | G173: 201261 | H173: 1 | I173: 1 | J173: 8 | K173: 8 | L173: 8 | M173: 8 | N173: 8 | O173: 40 | P173: 8 | R173: 0.08 | S173: SÍ — integrante | T173: B · INTEGRANTE | U173: DEL BANCO (se hereda) | V173: 9154 · OTRAS ACTIVIDADES NO CLASIFICADAS
C174: Actividad económica / giro mercantil | D174: F12 | E174: INHERENTE | F174: CRIA Y EXPLOTACION DE GANADO VACUNO PARA CARNE | G174: 211011 | H174: 2 | I174: 2 | J174: 8 | K174: 16 | L174: 16 | M174: 16 | N174: 16 | O174: 40 | P174: 8 | R174: 0.08 | S174: SÍ — integrante | T174: B · INTEGRANTE | U174: DEL BANCO (se hereda) | V174: 9151 · SECTOR PRIMARIO (agropecuario, pesca, forestal, minería)
C175: Actividad económica / giro mercantil | D175: F12 | E175: INHERENTE | F175: CRIA Y EXPLOTACION DE GANADO VACUNO PARA LECHE | G175: 212019 | H175: 2 | I175: 2 | J175: 8 | K175: 16 | L175: 16 | M175: 16 | N175: 16 | O175: 40 | P175: 8 | R175: 0.08 | S175: SÍ — integrante | T175: B · INTEGRANTE | U175: DEL BANCO (se hereda) | V175: 9151 · SECTOR PRIMARIO (agropecuario, pesca, forestal, minería)
C176: Actividad económica / giro mercantil | D176: F12 | E176: INHERENTE | F176: CRIA DE GANADO DE LIDIA | G176: 213017 | H176: 2 | I176: 2 | J176: 8 | K176: 16 | L176: 16 | M176: 16 | N176: 16 | O176: 40 | P176: 8 | R176: 0.08 | S176: SÍ — integrante | T176: B · INTEGRANTE | U176: DEL BANCO (se hereda) | V176: 9151 · SECTOR PRIMARIO (agropecuario, pesca, forestal, minería)
C177: Actividad económica / giro mercantil | D177: F12 | E177: INHERENTE | F177: CRIA DE GANADO CABALLAR | G177: 214015 | H177: 2 | I177: 2 | J177: 8 | K177: 16 | L177: 16 | M177: 16 | N177: 16 | O177: 40 | P177: 8 | R177: 0.08 | S177: SÍ — integrante | T177: B · INTEGRANTE | U177: DEL BANCO (se hereda) | V177: 9151 · SECTOR PRIMARIO (agropecuario, pesca, forestal, minería)
...

Sheet 5. MODELO EJEMPLO FID
A1: MODELO DE EJEMPLO — GRADO DE RIESGO DE UN FIDEICOMISO (interactivo: seleccione la VARIABLE)
A2: Instrumento de GRADO DE RIESGO DE CLIENTE — distinto e independiente de la MEBR/EBR de la entidad. Escala 100–500 y bandas de la Tabla 5 de la Matriz BX+ (modelo de clientes): 100–223 BAJO · 224–258 MEDIO · 259–290 MEDIO ALTO · 291–500 ALTO.
A3: Celdas azul claro = lista desplegable. NIVEL y PUNTAJE se calculan solos. El ROL es variable de riesgo (FI8) y además pondera la consolidación (decisión conservadora documentada en la GUÍA).
A5: BLOQUE A · EL VEHÍCULO (v2.6: sólo factores con dato en las bases de BX+)
A6: F | B6: FACTOR | C6: PESO % | D6: VARIABLE (elegir de la lista) | E6: NIVEL | F6: PUNTAJE
A7: FF1 | B7: Tipo de fideicomiso | C7: 0.3 | D7: FIDEICOMISO DE ADMINISTRACIÓN INMOBILIARIA (DESARROLLO O ARRENDAMIENTO) | E7: =IFERROR(INDEX(LISTAS!$B$5:$B$14,MATCH(D7,LISTAS!$A$5:$A$14,0)),"") | F7: =IFERROR(E7*C7*100,0)
A8: FF4 | B8: Antigüedad del fideicomiso | C8: 0.13 | D8: 3 A 10 AÑOS | E8: =IFERROR(INDEX(LISTAS!$E$5:$E$9,MATCH(D8,LISTAS!$D$5:$D$9,0)),"") | F8: =IFERROR(E8*C8*100,0)
A9: FF6 | B9: Actividad vulnerable LFPIORPI | C9: 0.27 | D9: AV CONFIRMADA ART. 17 (TIPO B) | E9: =IFERROR(INDEX(LISTAS!$H$5:$H$8,MATCH(D9,LISTAS!$G$5:$G$8,0)),"") | F9: =IFERROR(E9*C9*100,0)
A10: FF7 | B10: Procedencia de los recursos | C10: 0.19 | D10: VENTA DE ACTIVOS DOCUMENTADA (INMUEBLES, ACCIONES, ETC.) | E10: =IFERROR(INDEX(LISTAS!$K$5:$K$9,MATCH(D10,LISTAS!$J$5:$J$9,0)),"") | F10: =IFERROR(E10*C10*100,0)
A11: FF8 | B11: Operaciones en USD / transfronterizas | C11: 0.11 | D11: SIN OPERACIONES USD NI EXTRANJERO | E11: =IFERROR(INDEX(LISTAS!$N$5:$N$8,MATCH(D11,LISTAS!$M$5:$M$8,0)),"") | F11: =IFERROR(E11*C11*100,0)
B12: RIESGO ESTRUCTURAL DEL VEHÍCULO (100–500) | F12: =ROUND(SUM(F7:F11),0) | G12: =IF(F12>=291,"ALTO",IF(F12>=259,"MEDIO ALTO",IF(F12>=224,"MEDIO","BAJO")))
B14: RIESGO HEREDADO DEL BANCO (100–500): el mayor entre la Base SharePoint y SIPREV | F14: 241 | G14: =IF(F14>=291,"ALTO",IF(F14>=259,"MEDIO ALTO",IF(F14>=224,"MEDIO","BAJO")))
A16: Referencia del riesgo heredado: BAJO 162 · MEDIO 241 · MEDIO ALTO 275 · ALTO 330 (se sustituye por el puntaje real del banco). Fuera del cálculo en v2.6 (segunda fase): patrimonio aportado, valor, número de partes, ubicación y operación distinta al fin.
A19: BLOQUE B · LOS INTEGRANTES (incluye ROL como variable FI8)
A20: F | B20: FACTOR | C20: PESO % | D20: Inmobiliaria Delta SA — VARIABLE | E20: NIV | F20: Juan Pérez López — VARIABLE | G20: NIV | H20: Holding BV (extranjera) — VARIABLE | I20: NIV
A21: FI1 | B21: Tipo de persona | C21: 0.15 | D21: PERSONA MORAL | E21: =IFERROR(INDEX('3. BASE VARIABLES'!$H$2682:$H$2686,MATCH(D21,'3. BASE VARIABLES'!$F$2682:$F$2686,0)),"") | F21: PF CON ACTIVIDAD EMPRESARIAL | G21: =IFERROR(INDEX('3. BASE VARIABLES'!$H$2682:$H$2686,MATCH(F21,'3. BASE VARIABLES'!$F$2682:$F$2686,0)),"") | H21: PERSONA MORAL | I21: =IFERROR(INDEX('3. BASE VARIABLES'!$H$2682:$H$2686,MATCH(H21,'3. BASE VARIABLES'!$F$2682:$F$2686,0)),"")
A22: FI2 | B22: Actividad económica | C22: 0.23 | D22: INMOBILIARIO / CONSTRUCCIÓN | E22: =IFERROR(INDEX('3. BASE VARIABLES'!$H$2688:$H$2697,MATCH(D22,'3. BASE VARIABLES'!$F$2688:$F$2697,0)),"") | F22: SERVICIOS PROFESIONALES | G22: =IFERROR(INDEX('3. BASE VARIABLES'!$H$2688:$H$2697,MATCH(F22,'3. BASE VARIABLES'!$F$2688:$F$2697,0)),"") | H22: COMERCIO EXTERIOR | I22: =IFERROR(INDEX('3. BASE VARIABLES'!$H$2688:$H$2697,MATCH(H22,'3. BASE VARIABLES'!$F$2688:$F$2697,0)),"")
A23: FI3 | B23: País de nacimiento | C23: 0.09 | D23: MÉXICO | E23: =IFERROR(INDEX('3. BASE VARIABLES'!$H$2698:$H$2703,MATCH(D23,'3. BASE VARIABLES'!$F$2698:$F$2703,0)),"") | F23: MÉXICO | G23: =IFERROR(INDEX('3. BASE VARIABLES'!$H$2698:$H$2703,MATCH(F23,'3. BASE VARIABLES'!$F$2698:$F$2703,0)),"") | H23: RÉGIMEN FISCAL PREFERENTE | I23: =IFERROR(INDEX('3. BASE VARIABLES'!$H$2698:$H$2703,MATCH(H23,'3. BASE VARIABLES'!$F$2698:$F$2703,0)),"")
A24: FI4 | B24: Nacionalidad | C24: 0.11 | D24: MÉXICO | E24: =IFERROR(INDEX('3. BASE VARIABLES'!$H$2698:$H$2703,MATCH(D24,'3. BASE VARIABLES'!$F$2698:$F$2703,0)),"") | F24: MÉXICO | G24: =IFERROR(INDEX('3. BASE VARIABLES'!$H$2698:$H$2703,MATCH(F24,'3. BASE VARIABLES'!$F$2698:$F$2703,0)),"") | H24: RÉGIMEN FISCAL PREFERENTE | I24: =IFERROR(INDEX('3. BASE VARIABLES'!$H$2698:$H$2703,MATCH(H24,'3. BASE VARIABLES'!$F$2698:$F$2703,0)),"")
A25: FI5 | B25: País del domicilio | C25: 0.11 | D25: MÉXICO | E25: =IFERROR(INDEX('3. BASE VARIABLES'!$H$2698:$H$2703,MATCH(D25,'3. BASE VARIABLES'!$F$2698:$F$2703,0)),"") | F25: MÉXICO | G25: =IFERROR(INDEX('3. BASE VARIABLES'!$H$2698:$H$2703,MATCH(F25,'3. BASE VARIABLES'!$F$2698:$F$2703,0)),"") | H25: RÉGIMEN FISCAL PREFERENTE | I25: =IFERROR(INDEX('3. BASE VARIABLES'!$H$2698:$H$2703,MATCH(H25,'3. BASE VARIABLES'!$F$2698:$F$2703,0)),"")
A26: FI6 | B26: Estado del domicilio | C26: 0.12 | D26: INCIDENCIA MEDIA | E26: =IFERROR(INDEX('3. BASE VARIABLES'!$H$2704:$H$2708,MATCH(D26,'3. BASE VARIABLES'!$F$2704:$F$2708,0)),"") | F26: BAJA INCIDENCIA DELICTIVA | G26: =IFERROR(INDEX('3. BASE VARIABLES'!$H$2704:$H$2708,MATCH(F26,'3. BASE VARIABLES'!$F$2704:$F$2708,0)),"") | H26: DOMICILIO EN EL EXTRANJERO | I26: =IFERROR(INDEX('3. BASE VARIABLES'!$H$2704:$H$2708,MATCH(H26,'3. BASE VARIABLES'!$F$2704:$F$2708,0)),"")
A27: FI7 | B27: Edad / constitución | C27: 0.07 | D27: 3 A 10 AÑOS | E27: =IFERROR(INDEX('3. BASE VARIABLES'!$H$2709:$H$2717,MATCH(D27,'3. BASE VARIABLES'!$F$2709:$F$2717,0)),"") | F27: 25 A 50 AÑOS | G27: =IFERROR(INDEX('3. BASE VARIABLES'!$H$2709:$H$2717,MATCH(F27,'3. BASE VARIABLES'!$F$2709:$F$2717,0)),"") | H27: 1 A 3 AÑOS | I27: =IFERROR(INDEX('3. BASE VARIABLES'!$H$2709:$H$2717,MATCH(H27,'3. BASE VARIABLES'!$F$2709:$F$2717,0)),"")
A28: FI8 | B28: Rol en el fideicomiso | C28: 0.12 | D28: FIDEICOMITENTE | E28: =IFERROR(INDEX('3. BASE VARIABLES'!$H$2674:$H$2679,MATCH(D28,'3. BASE VARIABLES'!$F$2674:$F$2679,0)),"") | F28: FIDEICOMISARIO | G28: =IFERROR(INDEX('3. BASE VARIABLES'!$H$2674:$H$2679,MATCH(F28,'3. BASE VARIABLES'!$F$2674:$F$2679,0)),"") | H28: MIEMBRO DEL COMITÉ TÉCNICO | I28: =IFERROR(INDEX('3. BASE VARIABLES'!$H$2674:$H$2679,MATCH(H28,'3. BASE VARIABLES'!$F$2674:$F$2679,0)),"")
B30: RIESGO DEL INTEGRANTE (100–500) | D30: =ROUND(SUMPRODUCT($C$21:$C$28,E21:E28)*100,0) | F30: =ROUND(SUMPRODUCT($C$21:$C$28,G21:G28)*100,0) | H30: =ROUND(SUMPRODUCT($C$21:$C$28,I21:I28)*100,0)
B31: BANDA | D31: =IF(D30>=291,"ALTO",IF(D30>=259,"MEDIO ALTO",IF(D30>=224,"MEDIO","BAJO"))) | F31: =IF(F30>=291,"ALTO",IF(F30>=259,"MEDIO ALTO",IF(F30>=224,"MEDIO","BAJO"))) | H31: =IF(H30>=291,"ALTO",IF(H30>=259,"MEDIO ALTO",IF(H30>=224,"MEDIO","BAJO")))
A34: BLOQUE C · CONSOLIDACIÓN (el rol pondera: se toma de la fila FI8)
B35: Peso de rol | D35: =IF(LEFT(D28,14)="FIDEICOMITENTE",0.4,IF(LEFT(D28,10)="MIEMBRO DE",0.2,IF(LEFT(D28,14)="FIDEICOMISARIO",0.25,0.15))) | F35: =IF(LEFT(F28,14)="FIDEICOMITENTE",0.4,IF(LEFT(F28,10)="MIEMBRO DE",0.2,IF(LEFT(F28,14)="FIDEICOMISARIO",0.25,0.15))) | H35: =IF(LEFT(H28,14)="FIDEICOMITENTE",0.4,IF(LEFT(H28,10)="MIEMBRO DE",0.2,IF(LEFT(H28,14)="FIDEICOMISARIO",0.25,0.15)))
B36: Peso normalizado | D36: =D35/($D$35+$F$35+$H$35) | F36: =F35/($D$35+$F$35+$H$35) | H36: =H35/($D$35+$F$35+$H$35)
B37: Promedio ponderado de integrantes | D37: =ROUND(D30*D36+F30*F36+H30*H36,0)
B38: Peor parte | D38: =MAX(D30,F30,H30)
B39: Estructural del vehículo | D39: =F12
B40: GRADO DE RIESGO CONSOLIDADO (antes de invalidaciones) | D40: =MAX(D37,D39,D41,IF(D38>=291,D38,0)) | E40: =IF(D40>=291,"ALTO",IF(D40>=259,"MEDIO ALTO",IF(D40>=224,"MEDIO","BAJO")))
B41: Riesgo heredado del banco | D41: =F14
B43: ¿Invalidación prohibitiva? (B1–B3, hoja INVALIDACIONES) | D43: NO
B44: ¿Invalidación de alto riesgo? (A1–A8, hoja INVALIDACIONES) | D44: NO
B46: CALIFICACIÓN FINAL DEL FIDEICOMISO | D46: =IF(D43="SI",500,IF(D44="SI",MAX(D40,291),D40)) | E46: =IF(D43="SI","PROHIBITIVO",IF(D46>=291,"ALTO",IF(D46>=259,"MEDIO ALTO",IF(D46>=224,"MEDIO","BAJO"))))

Sheet CAPTURA INTEGRANTES
A1: CAPTURA MASIVA — UNA LÍNEA POR INTEGRANTE
A2: Captura manual por integrante para cuando exista la información (la base del banco no trae integrantes). No participa en la BASE DE CARGA de esta versión.
A4: ID FIDEICOMISO | B4: INTEGRANTE | C4: ROL | D4: FI1 | E4: FI2 | F4: FI3 | G4: FI4 | H4: FI5 | I4: FI6 | J4: FI7 | K4: RIESGO | L4: BANDA | M4: PESO ROL | N4: APORTE | O4: INVALIDACIÓN
A5: F/0001 | B5: Inmobiliaria Delta SA | C5: Fideicomitente | D5: 3 | E5: 4 | F5: 1 | G5: 1 | H5: 1 | I5: 2 | J5: 2 | K5: =SUMPRODUCT(D5:J5,{15,23,9,11,11,12,7})+IF(C5="Fideicomitente",4,IF(C5="Fideicomisario",3,IF(C5="Comité técnico",4,3)))*12 | L5: =IF(K5>=291,"ALTO",IF(K5>=259,"MEDIO ALTO",IF(K5>=224,"MEDIO","BAJO"))) | M5: =IF(C5="Fideicomitente",0.4,IF(C5="Fideicomisario",0.25,IF(C5="Comité técnico",0.2,0.15))) | N5: =K5*M5
A6: F/0001 | B6: Juan Pérez López | C6: Fideicomisario | D6: 1 | E6: 2 | F6: 1 | G6: 1 | H6: 1 | I6: 2 | J6: 1 | K6: =SUMPRODUCT(D6:J6,{15,23,9,11,11,12,7})+IF(C6="Fideicomitente",4,IF(C6="Fideicomisario",3,IF(C6="Comité técnico",4,3)))*12 | L6: =IF(K6>=291,"ALTO",IF(K6>=259,"MEDIO ALTO",IF(K6>=224,"MEDIO","BAJO"))) | M6: =IF(C6="Fideicomitente",0.4,IF(C6="Fideicomisario",0.25,IF(C6="Comité técnico",0.2,0.15))) | N6: =K6*M6
A7: F/0001 | B7: Holding BV (extranjera) | C7: Comité técnico | D7: 5 | E7: 3 | F7: 4 | G7: 4 | H7: 4 | I7: 1 | J7: 2 | K7: =SUMPRODUCT(D7:J7,{15,23,9,11,11,12,7})+IF(C7="Fideicomitente",4,IF(C7="Fideicomisario",3,IF(C7="Comité técnico",4,3)))*12 | L7: =IF(K7>=291,"ALTO",IF(K7>=259,"MEDIO ALTO",IF(K7>=224,"MEDIO","BAJO"))) | M7: =IF(C7="Fideicomitente",0.4,IF(C7="Fideicomisario",0.25,IF(C7="Comité técnico",0.2,0.15))) | N7: =K7*M7
A8: F/0002 | B8: Constructora Gama SA | C8: Fideicomitente | D8: 3 | E8: 5 | F8: 1 | G8: 1 | H8: 1 | I8: 3 | J8: 3 | K8: =SUMPRODUCT(D8:J8,{15,23,9,11,11,12,7})+IF(C8="Fideicomitente",4,IF(C8="Fideicomisario",3,IF(C8="Comité técnico",4,3)))*12 | L8: =IF(K8>=291,"ALTO",IF(K8>=259,"MEDIO ALTO",IF(K8>=224,"MEDIO","BAJO"))) | M8: =IF(C8="Fideicomitente",0.4,IF(C8="Fideicomisario",0.25,IF(C8="Comité técnico",0.2,0.15))) | N8: =K8*M8
A9: F/0002 | B9: María Ruiz (PF) | C9: Fideicomisario | D9: 1 | E9: 2 | F9: 1 | G9: 1 | H9: 1 | I9: 2 | J9: 1 | K9: =SUMPRODUCT(D9:J9,{15,23,9,11,11,12,7})+IF(C9="Fideicomitente",4,IF(C9="Fideicomisario",3,IF(C9="Comité técnico",4,3)))*12 | L9: =IF(K9>=291,"ALTO",IF(K9>=259,"MEDIO ALTO",IF(K9>=224,"MEDIO","BAJO"))) | M9: =IF(C9="Fideicomitente",0.4,IF(C9="Fideicomisario",0.25,IF(C9="Comité técnico",0.2,0.15))) | N9: =K9*M9
A10: F/0003 | B10: Fondo Omega SAPI | C10: Fideicomitente | D10: 3 | E10: 3 | F10: 1 | G10: 1 | H10: 1 | I10: 2 | J10: 2 | K10: =SUMPRODUCT(D10:J10,{15,23,9,11,11,12,7})+IF(C10="Fideicomitente",4,IF(C10="Fideicomisario",3,IF(C10="Comité técnico",4,3)))*12 | L10: =IF(K10>=291,"ALTO",IF(K10>=259,"MEDIO ALTO",IF(K10>=224,"MEDIO","BAJO"))) | M10: =IF(C10="Fideicomitente",0.4,IF(C10="Fideicomisario",0.25,IF(C10="Comité técnico",0.2,0.15))) | N10: =K10*M10
A11: F/0003 | B11: Beneficiarios diversos | C11: Fideicomisario | D11: 1 | E11: 1 | F11: 1 | G11: 1 | H11: 1 | I11: 2 | J11: 1 | K11: =SUMPRODUCT(D11:J11,{15,23,9,11,11,12,7})+IF(C11="Fideicomitente",4,IF(C11="Fideicomisario",3,IF(C11="Comité técnico",4,3)))*12 | L11: =IF(K11>=291,"ALTO",IF(K11>=259,"MEDIO ALTO",IF(K11>=224,"MEDIO","BAJO"))) | M11: =IF(C11="Fideicomitente",0.4,IF(C11="Fideicomisario",0.25,IF(C11="Comité técnico",0.2,0.15))) | N11: =K11*M11
A12: F/0003 | B12: Apoderado legal | C12: Apoderado/tercero | D12: 1 | E12: 2 | F12: 1 | G12: 1 | H12: 1 | I12: 2 | J12: 1 | K12: =SUMPRODUCT(D12:J12,{15,23,9,11,11,12,7})+IF(C12="Fideicomitente",4,IF(C12="Fideicomisario",3,IF(C12="Comité técnico",4,3)))*12 | L12: =IF(K12>=291,"ALTO",IF(K12>=259,"MEDIO ALTO",IF(K12>=224,"MEDIO","BAJO"))) | M12: =IF(C12="Fideicomitente",0.4,IF(C12="Fideicomisario",0.25,IF(C12="Comité técnico",0.2,0.15))) | N12: =K12*M12
A15: INVALIDACIÓN: escribir B (lista sanciones → PROHIBITIVO) o A (PEP / BC sin identificar / GAFI gris → mínimo ALTO). Vacío = sin invalidación.

Sheet MATRIZ CONSOLIDADA
A1: MATRIZ CONSOLIDADA — ESTADÍSTICA DE TODA LA BASE
A2: Fórmulas COUNTIFS sobre CAPTURA FIDEICOMISOS: se actualiza sola al capturar (sin tablas dinámicas ni 'actualizar').
A4: DISTRIBUCIÓN POR BANDA DE RIESGO | E4: INTEGRANTES POR BANDA
A5: BANDA | B5: FIDEICOMISOS | C5: % DE LA BASE | E5: RIESGO HEREDADO DEL BANCO | F5: FIDEICOMISOS
A6: BAJO | B6: =COUNTIFS('BASE DE CARGA'!AF:AF,"BAJO") | C6: =IFERROR(B6/B$10,0) | E6: BAJO | F6: =COUNTIFS('BASE DE CARGA'!S:S,162)
A7: MEDIO | B7: =COUNTIFS('BASE DE CARGA'!AF:AF,"MEDIO") | C7: =IFERROR(B7/B$10,0) | E7: MEDIO | F7: =COUNTIFS('BASE DE CARGA'!S:S,241)
A8: MEDIO ALTO | B8: =COUNTIFS('BASE DE CARGA'!AF:AF,"MEDIO ALTO") | C8: =IFERROR(B8/B$10,0) | E8: MEDIO ALTO | F8: =COUNTIFS('BASE DE CARGA'!S:S,275)
A9: ALTO | B9: =COUNTIFS('BASE DE CARGA'!AF:AF,"ALTO") | C9: =IFERROR(B9/B$10,0) | E9: ALTO | F9: =COUNTIFS('BASE DE CARGA'!S:S,330)
A10: TOTAL | B10: =COUNTA('BASE DE CARGA'!A6:A3000) | C10: =SUM(C6:C9)
A13: INVALIDACIONES ACTIVAS
A14: TIPO | B14: FIDEICOMISOS
A15: PROHIBITIVO (B) | B15: =COUNTIFS('BASE DE CARGA'!AD:AD,"B")
A16: MÍNIMO ALTO (A) | B16: =COUNTIFS('BASE DE CARGA'!AD:AD,"A")
A19: PROMEDIO Y EXTREMOS (100–500)
A20: MÉTRICA | B20: VALOR
A21: Promedio consolidado | B21: =ROUND(AVERAGE('BASE DE CARGA'!AE6:AE3000),0)
A22: Máximo | B22: =MAX('BASE DE CARGA'!AE6:AE3000)
A23: Mínimo | B23: =MIN('BASE DE CARGA'!AE6:AE3000)
A25: SUBIERON RESPECTO AL BANCO
A26: Fideicomisos con calificación final mayor al riesgo heredado | B26: =SUMPRODUCT(--('BASE DE CARGA'!AE6:AE3000>'BASE DE CARGA'!S6:S3000))

Sheet LISTAS
A1: LISTAS — catálogos del vehículo usados en el modelo de ejemplo
A2: Se alimentan de 3. BASE VARIABLES. No editar aquí: cambiar nivel o nombre en la base de variables y copiar.
A4: FF1 · variable | B4: Nivel | D4: FF4 · variable | E4: Nivel | G4: FF6 · variable | H4: Nivel | J4: FF7 · variable | K4: Nivel | M4: FF8 · variable | N4: Nivel
A5: FIDEICOMISO DE ADMINISTRACIÓN | B5: 2 | D5: MENOS DE 1 AÑO | E5: 5 | G5: SIN ACTIVIDAD VULNERABLE (TIPO A) | H5: 1 | J5: RECURSOS BANCARIZADOS CON SOPORTE (AHORROS, DIVIDENDOS, SALARIOS, ETC.) | K5: 1 | M5: SIN OPERACIONES USD NI EXTRANJERO | N5: 1
A6: FIDEICOMISO DE GARANTÍA | B6: 2 | D6: 1 A 3 AÑOS | E6: 4 | G6: AV POTENCIAL / EN DICTAMEN (TIPO C) | H6: 3 | J6: VENTA DE ACTIVOS DOCUMENTADA (INMUEBLES, ACCIONES, ETC.) | K6: 2 | M6: USD OCASIONAL / PARTE EXTRANJERA | N6: 3
A7: FIDEICOMISO DE INVERSIÓN | B7: 3 | D7: 3 A 10 AÑOS | E7: 2 | G7: AV CONFIRMADA ART. 17 (TIPO B) | H7: 5 | J7: APORTACIÓN EN ESPECIE SIN AVALÚO RECIENTE | K7: 4 | M7: FLUJOS RECURRENTES USD O JURISDICCIÓN DE RIESGO | N7: 5
A8: FIDEICOMISO FUENTE DE PAGO | B8: 3 | D8: MÁS DE 10 AÑOS | E8: 1 | G8: NO DETERMINADO | H8: 2.58 | J8: ORIGEN NO VERIFICABLE / EXTRANJERO SIN SOPORTE | K8: 5 | M8: NO DETERMINADO | N8: 2.58
A9: FIDEICOMISO TESTAMENTARIO / PLANEACIÓN PATRIMONIAL | B9: 2 | D9: NO DETERMINADO | E9: 2.58 | J9: NO DETERMINADO | K9: 2.58
A10: FIDEICOMISO TRASLATIVO DE DOMINIO | B10: 5
A11: FIDEICOMISO RECIBIDO POR SUSTITUCIÓN FIDUCIARIA | B11: 4
A12: FIDEICOMISO ZONA RESTRINGIDA | B12: 4
A13: FIDEICOMISO DE ADMINISTRACIÓN INMOBILIARIA (DESARROLLO O ARRENDAMIENTO) | B13: 3
A14: NO DETERMINADO | B14: 2.58

Sheet CAMBIOS v2.5
A1: MATRIZ DE RIESGO FIDEICOMISOS · CAMBIOS v2.4 → v2.5
A2: Incorpora los comentarios de Héctor Camacho (archivo vr_HCS, 23-sep-2026) en lenguaje más básico. No cambia ningún nivel, peso ni multiplicador. Celdas modificadas en azul (#2c5282) en su hoja.
A4: Hoja | B4: Celda | C4: Texto v2.4 | D4: Propuesta / comentario de Héctor | E4: Texto v2.5 | F4: Criterio | G4: Estado
A5: 3. BASE VARIABLES | B5: F2639 | C5: FIDEICOMISO TESTAMENTARIO | D5: FIDEICOMISO TESTAMENTARIO PLANEACIÓN PATRIMONIAL | E5: FIDEICOMISO TESTAMENTARIO / PLANEACIÓN PATRIMONIAL | F5: Se acepta; sólo se agrega la diagonal. | G5: Aplicado
A6: 3. BASE VARIABLES | B6: F2641 | C6: FIDEICOMISO PÚBLICO / GUBERNAMENTAL | D6: FIDEICOMISO PÚBLICO / GUBERNAMENTAL SUSTITUCION | E6: FIDEICOMISO RECIBIDO POR SUSTITUCIÓN FIDUCIARIA | F6: Petición de Héctor: los públicos no son alcance de Fiduciario. Nivel 4 conservado (expediente KYC heredado del fiduciario anterior). Recomendación: a futuro registrar la sustitución como dato de origen, separado del tipo. | G6: Aplicado · confirmar nivel en sesión
A7: 3. BASE VARIABLES | B7: F2643 | C7: EFECTIVO / VALORES BURSÁTILES | D7: EFECTIVO/VALORES BURSÁTILES CANTIDADES EN NUMERARIO | E7: EFECTIVO (NUMERARIO) / VALORES BURSÁTILES COTIZADOS EN CUSTODIA | F7: Se acepta «numerario»; se precisa «cotizados en custodia» para distinguirlo de los títulos no cotizados (nivel 4). | G7: Aplicado
A8: 3. BASE VARIABLES | B8: F2644 | C8: INMUEBLES | D8: INMUEBLES [AGREGAR MUEBLES] | E8: INMUEBLES Y BIENES MUEBLES (VEHÍCULOS, ARTE, JOYAS, MAQUINARIA) | F8: Se agregan muebles en la misma opción, nivel 3. Alternativa a decidir: muebles como opción propia en nivel 4 por dificultad de valuación. | G8: Aplicado · decidir en sesión
A9: 3. BASE VARIABLES | B9: F2645 | C9: ACCIONES / PARTES SOCIALES | D9: TITULOS DE VALOR(ACCIONES, PARTES SOCIALES, ETC) | E9: ACCIONES, PARTES SOCIALES Y OTROS TÍTULOS NO COTIZADOS | F9: Las partes sociales no son títulos de crédito; y «no cotizados» evita el empalme con valores bursátiles (nivel 1). | G9: Aplicado
A10: 3. BASE VARIABLES | B10: F2646 | C10: DERECHOS DE COBRO / OTROS BIENES | D10: DERECHOS(DE COBRO, FIDEICOMISARIOS, ETC) / OTROS BIENES | E10: DERECHOS (DE COBRO, FIDEICOMISARIOS, ETC.) / OTROS BIENES | F10: Se acepta. | G10: Aplicado
A11: 3. BASE VARIABLES | B11: F2647 | C11: MIXTO (EFECTIVO + ESPECIE) | D11: MIXTO (EFECTIVO NUMERARIO + ESPECIE) | E11: MIXTO (EFECTIVO EN NUMERARIO + ESPECIE) | F11: Se acepta. | G11: Aplicado
A12: 3. BASE VARIABLES | B12: F2664 | C12: RECURSOS BANCARIZADOS CON SOPORTE | D12: RECURSOS BANCARIZADOS CON SOPORTE(AHORROS, DIVIDENDOS, SALARIOS, ETC…) | E12: RECURSOS BANCARIZADOS CON SOPORTE (AHORROS, DIVIDENDOS, SALARIOS, ETC.) | F12: Se acepta. | G12: Aplicado
A13: 3. BASE VARIABLES | B13: F2665 | C13: VENTA DE ACTIVOS DOCUMENTADA | D13: VENTA DE ACTIVOS DOCUMENTADA(INMUEBLES, ACCIONES, ETC) | E13: VENTA DE ACTIVOS DOCUMENTADA (INMUEBLES, ACCIONES, ETC.) | F13: Se acepta. | G13: Aplicado
A14: 3. BASE VARIABLES | B14: C2671 | C14: DESVIACIÓN DEL FIN (V2) | D14: Comentario: «No veo una desviación» | E14: OPERACIÓN DISTINTA AL FIN DEL CONTRATO (V2) | F14: Lenguaje llano: la etiqueta «desviación del fin» no se entendía. Mismo factor FF9, mismos niveles; sigue siendo V2. | G14: Aplicado
